[15/Mar/2022 16:00:38] |ERROR| Internal Server Error: /e-shop/index
Traceback (most recent call last):
  File "/usr/local/lib/python3.9/site-packages/django/db/backends/base/base.py", line 219, in ensure_connection
    self.connect()
  File "/usr/local/lib/python3.9/site-packages/django/utils/asyncio.py", line 26, in inner
    return func(*args, **kwargs)
  File "/usr/local/lib/python3.9/site-packages/django/db/backends/base/base.py", line 200, in connect
    self.connection = self.get_new_connection(conn_params)
  File "/usr/local/lib/python3.9/site-packages/django/utils/asyncio.py", line 26, in inner
    return func(*args, **kwargs)
  File "/usr/local/lib/python3.9/site-packages/django/db/backends/postgresql/base.py", line 187, in get_new_connection
    connection = Database.connect(**conn_params)
  File "/usr/local/lib/python3.9/site-packages/psycopg2/__init__.py", line 122, in connect
    conn = _connect(dsn, connection_factory=connection_factory, **kwasync)
psycopg2.OperationalError: connection to server at "db" (172.18.0.2), port 5432 failed: fe_sendauth: no password supplied


The above exception was the direct cause of the following exception:

Traceback (most recent call last):
  File "/usr/local/lib/python3.9/site-packages/django/core/handlers/exception.py", line 47, in inner
    response = get_response(request)
  File "/usr/local/lib/python3.9/site-packages/django/core/handlers/base.py", line 181, in _get_response
    response = wrapped_callback(request, *callback_args, **callback_kwargs)
  File "/usr/local/lib/python3.9/site-packages/django/views/generic/base.py", line 70, in view
    return self.dispatch(request, *args, **kwargs)
  File "/usr/local/lib/python3.9/site-packages/django/views/generic/base.py", line 98, in dispatch
    return handler(request, *args, **kwargs)
  File "/usr/local/lib/python3.9/site-packages/django/views/generic/list.py", line 157, in get
    context = self.get_context_data()
  File "/opt/back_end/shop/e_shop/views.py", line 111, in get_context_data
    context = super().get_context_data(**kwargs)
  File "/usr/local/lib/python3.9/site-packages/django/views/generic/list.py", line 119, in get_context_data
    paginator, page, queryset, is_paginated = self.paginate_queryset(queryset, page_size)
  File "/usr/local/lib/python3.9/site-packages/django/views/generic/list.py", line 69, in paginate_queryset
    page = paginator.page(page_number)
  File "/usr/local/lib/python3.9/site-packages/django/core/paginator.py", line 76, in page
    number = self.validate_number(number)
  File "/usr/local/lib/python3.9/site-packages/django/core/paginator.py", line 54, in validate_number
    if number > self.num_pages:
  File "/usr/local/lib/python3.9/site-packages/django/utils/functional.py", line 48, in __get__
    res = instance.__dict__[self.name] = self.func(instance)
  File "/usr/local/lib/python3.9/site-packages/django/core/paginator.py", line 103, in num_pages
    if self.count == 0 and not self.allow_empty_first_page:
  File "/usr/local/lib/python3.9/site-packages/django/utils/functional.py", line 48, in __get__
    res = instance.__dict__[self.name] = self.func(instance)
  File "/usr/local/lib/python3.9/site-packages/django/core/paginator.py", line 97, in count
    return c()
  File "/usr/local/lib/python3.9/site-packages/django/db/models/query.py", line 412, in count
    return self.query.get_count(using=self.db)
  File "/usr/local/lib/python3.9/site-packages/django/db/models/sql/query.py", line 517, in get_count
    number = obj.get_aggregation(using, ['__count'])['__count']
  File "/usr/local/lib/python3.9/site-packages/django/db/models/sql/query.py", line 502, in get_aggregation
    result = compiler.execute_sql(SINGLE)
  File "/usr/local/lib/python3.9/site-packages/django/db/models/sql/compiler.py", line 1173, in execute_sql
    cursor = self.connection.cursor()
  File "/usr/local/lib/python3.9/site-packages/django/utils/asyncio.py", line 26, in inner
    return func(*args, **kwargs)
  File "/usr/local/lib/python3.9/site-packages/django/db/backends/base/base.py", line 259, in cursor
    return self._cursor()
  File "/usr/local/lib/python3.9/site-packages/django/db/backends/base/base.py", line 235, in _cursor
    self.ensure_connection()
  File "/usr/local/lib/python3.9/site-packages/django/utils/asyncio.py", line 26, in inner
    return func(*args, **kwargs)
  File "/usr/local/lib/python3.9/site-packages/django/db/backends/base/base.py", line 219, in ensure_connection
    self.connect()
  File "/usr/local/lib/python3.9/site-packages/django/db/utils.py", line 90, in __exit__
    raise dj_exc_value.with_traceback(traceback) from exc_value
  File "/usr/local/lib/python3.9/site-packages/django/db/backends/base/base.py", line 219, in ensure_connection
    self.connect()
  File "/usr/local/lib/python3.9/site-packages/django/utils/asyncio.py", line 26, in inner
    return func(*args, **kwargs)
  File "/usr/local/lib/python3.9/site-packages/django/db/backends/base/base.py", line 200, in connect
    self.connection = self.get_new_connection(conn_params)
  File "/usr/local/lib/python3.9/site-packages/django/utils/asyncio.py", line 26, in inner
    return func(*args, **kwargs)
  File "/usr/local/lib/python3.9/site-packages/django/db/backends/postgresql/base.py", line 187, in get_new_connection
    connection = Database.connect(**conn_params)
  File "/usr/local/lib/python3.9/site-packages/psycopg2/__init__.py", line 122, in connect
    conn = _connect(dsn, connection_factory=connection_factory, **kwasync)
django.db.utils.OperationalError: connection to server at "db" (172.18.0.2), port 5432 failed: fe_sendauth: no password supplied

[15/Mar/2022 16:00:39] |DEBUG| Exception while resolving variable 'name' in template 'unknown'.
Traceback (most recent call last):
  File "/usr/local/lib/python3.9/site-packages/django/core/handlers/exception.py", line 47, in inner
    response = get_response(request)
  File "/usr/local/lib/python3.9/site-packages/django/core/handlers/base.py", line 167, in _get_response
    callback, callback_args, callback_kwargs = self.resolve_request(request)
  File "/usr/local/lib/python3.9/site-packages/django/core/handlers/base.py", line 290, in resolve_request
    resolver_match = resolver.resolve(request.path_info)
  File "/usr/local/lib/python3.9/site-packages/django/urls/resolvers.py", line 585, in resolve
    raise Resolver404({'tried': tried, 'path': new_path})
django.urls.exceptions.Resolver404: {'tried': [[<URLResolver <URLPattern list> (admin:admin) 'admin/'>], [<URLResolver <module 'e_shop.urls' from '/opt/back_end/shop/e_shop/urls.py'> (None:None) 'e-shop/'>], [<URLPattern 'api-docs/' [name='swagger-ui']>], [<URLPattern 'openapi' [name='openapi-schema']>], [<URLPattern '^images/(?P<path>.*)$'>]], 'path': 'favicon.ico'}

During handling of the above exception, another exception occurred:

Traceback (most recent call last):
  File "/usr/local/lib/python3.9/site-packages/django/template/base.py", line 829, in _resolve_lookup
    current = current[bit]
TypeError: 'URLResolver' object is not subscriptable

During handling of the above exception, another exception occurred:

Traceback (most recent call last):
  File "/usr/local/lib/python3.9/site-packages/django/template/base.py", line 837, in _resolve_lookup
    current = getattr(current, bit)
AttributeError: 'URLResolver' object has no attribute 'name'

During handling of the above exception, another exception occurred:

Traceback (most recent call last):
  File "/usr/local/lib/python3.9/site-packages/django/template/base.py", line 843, in _resolve_lookup
    current = current[int(bit)]
ValueError: invalid literal for int() with base 10: 'name'

During handling of the above exception, another exception occurred:

Traceback (most recent call last):
  File "/usr/local/lib/python3.9/site-packages/django/template/base.py", line 848, in _resolve_lookup
    raise VariableDoesNotExist("Failed lookup for key "
django.template.base.VariableDoesNotExist: Failed lookup for key [name] in <URLResolver <URLPattern list> (admin:admin) 'admin/'>
[15/Mar/2022 16:00:39] |DEBUG| Exception while resolving variable 'name' in template 'unknown'.
Traceback (most recent call last):
  File "/usr/local/lib/python3.9/site-packages/django/core/handlers/exception.py", line 47, in inner
    response = get_response(request)
  File "/usr/local/lib/python3.9/site-packages/django/core/handlers/base.py", line 167, in _get_response
    callback, callback_args, callback_kwargs = self.resolve_request(request)
  File "/usr/local/lib/python3.9/site-packages/django/core/handlers/base.py", line 290, in resolve_request
    resolver_match = resolver.resolve(request.path_info)
  File "/usr/local/lib/python3.9/site-packages/django/urls/resolvers.py", line 585, in resolve
    raise Resolver404({'tried': tried, 'path': new_path})
django.urls.exceptions.Resolver404: {'tried': [[<URLResolver <URLPattern list> (admin:admin) 'admin/'>], [<URLResolver <module 'e_shop.urls' from '/opt/back_end/shop/e_shop/urls.py'> (None:None) 'e-shop/'>], [<URLPattern 'api-docs/' [name='swagger-ui']>], [<URLPattern 'openapi' [name='openapi-schema']>], [<URLPattern '^images/(?P<path>.*)$'>]], 'path': 'favicon.ico'}

During handling of the above exception, another exception occurred:

Traceback (most recent call last):
  File "/usr/local/lib/python3.9/site-packages/django/template/base.py", line 829, in _resolve_lookup
    current = current[bit]
TypeError: 'URLResolver' object is not subscriptable

During handling of the above exception, another exception occurred:

Traceback (most recent call last):
  File "/usr/local/lib/python3.9/site-packages/django/template/base.py", line 837, in _resolve_lookup
    current = getattr(current, bit)
AttributeError: 'URLResolver' object has no attribute 'name'

During handling of the above exception, another exception occurred:

Traceback (most recent call last):
  File "/usr/local/lib/python3.9/site-packages/django/template/base.py", line 843, in _resolve_lookup
    current = current[int(bit)]
ValueError: invalid literal for int() with base 10: 'name'

During handling of the above exception, another exception occurred:

Traceback (most recent call last):
  File "/usr/local/lib/python3.9/site-packages/django/template/base.py", line 848, in _resolve_lookup
    raise VariableDoesNotExist("Failed lookup for key "
django.template.base.VariableDoesNotExist: Failed lookup for key [name] in <URLResolver <module 'e_shop.urls' from '/opt/back_end/shop/e_shop/urls.py'> (None:None) 'e-shop/'>
[15/Mar/2022 16:00:39] |WARNING| Not Found: /favicon.ico
[15/Mar/2022 16:02:35] |ERROR| Internal Server Error: /admin/
Traceback (most recent call last):
  File "/usr/local/lib/python3.9/site-packages/django/contrib/sessions/backends/base.py", line 233, in _get_session
    return self._session_cache
AttributeError: 'SessionStore' object has no attribute '_session_cache'

During handling of the above exception, another exception occurred:

Traceback (most recent call last):
  File "/usr/local/lib/python3.9/site-packages/django/db/backends/base/base.py", line 219, in ensure_connection
    self.connect()
  File "/usr/local/lib/python3.9/site-packages/django/utils/asyncio.py", line 26, in inner
    return func(*args, **kwargs)
  File "/usr/local/lib/python3.9/site-packages/django/db/backends/base/base.py", line 200, in connect
    self.connection = self.get_new_connection(conn_params)
  File "/usr/local/lib/python3.9/site-packages/django/utils/asyncio.py", line 26, in inner
    return func(*args, **kwargs)
  File "/usr/local/lib/python3.9/site-packages/django/db/backends/postgresql/base.py", line 187, in get_new_connection
    connection = Database.connect(**conn_params)
  File "/usr/local/lib/python3.9/site-packages/psycopg2/__init__.py", line 122, in connect
    conn = _connect(dsn, connection_factory=connection_factory, **kwasync)
psycopg2.OperationalError: connection to server at "db" (172.18.0.2), port 5432 failed: fe_sendauth: no password supplied


The above exception was the direct cause of the following exception:

Traceback (most recent call last):
  File "/usr/local/lib/python3.9/site-packages/django/core/handlers/exception.py", line 47, in inner
    response = get_response(request)
  File "/usr/local/lib/python3.9/site-packages/django/core/handlers/base.py", line 181, in _get_response
    response = wrapped_callback(request, *callback_args, **callback_kwargs)
  File "/usr/local/lib/python3.9/site-packages/django/contrib/admin/sites.py", line 250, in wrapper
    return self.admin_view(view, cacheable)(*args, **kwargs)
  File "/usr/local/lib/python3.9/site-packages/django/utils/decorators.py", line 130, in _wrapped_view
    response = view_func(request, *args, **kwargs)
  File "/usr/local/lib/python3.9/site-packages/django/views/decorators/cache.py", line 44, in _wrapped_view_func
    response = view_func(request, *args, **kwargs)
  File "/usr/local/lib/python3.9/site-packages/django/contrib/admin/sites.py", line 221, in inner
    if not self.has_permission(request):
  File "/usr/local/lib/python3.9/site-packages/django/contrib/admin/sites.py", line 195, in has_permission
    return request.user.is_active and request.user.is_staff
  File "/usr/local/lib/python3.9/site-packages/django/utils/functional.py", line 246, in inner
    self._setup()
  File "/usr/local/lib/python3.9/site-packages/django/utils/functional.py", line 382, in _setup
    self._wrapped = self._setupfunc()
  File "/usr/local/lib/python3.9/site-packages/django/contrib/auth/middleware.py", line 23, in <lambda>
    request.user = SimpleLazyObject(lambda: get_user(request))
  File "/usr/local/lib/python3.9/site-packages/django/contrib/auth/middleware.py", line 11, in get_user
    request._cached_user = auth.get_user(request)
  File "/usr/local/lib/python3.9/site-packages/django/contrib/auth/__init__.py", line 177, in get_user
    user_id = _get_user_session_key(request)
  File "/usr/local/lib/python3.9/site-packages/django/contrib/auth/__init__.py", line 60, in _get_user_session_key
    return get_user_model()._meta.pk.to_python(request.session[SESSION_KEY])
  File "/usr/local/lib/python3.9/site-packages/django/contrib/sessions/backends/base.py", line 65, in __getitem__
    return self._session[key]
  File "/usr/local/lib/python3.9/site-packages/django/contrib/sessions/backends/base.py", line 238, in _get_session
    self._session_cache = self.load()
  File "/usr/local/lib/python3.9/site-packages/django/contrib/sessions/backends/db.py", line 43, in load
    s = self._get_session_from_db()
  File "/usr/local/lib/python3.9/site-packages/django/contrib/sessions/backends/db.py", line 32, in _get_session_from_db
    return self.model.objects.get(
  File "/usr/local/lib/python3.9/site-packages/django/db/models/manager.py", line 85, in manager_method
    return getattr(self.get_queryset(), name)(*args, **kwargs)
  File "/usr/local/lib/python3.9/site-packages/django/db/models/query.py", line 431, in get
    num = len(clone)
  File "/usr/local/lib/python3.9/site-packages/django/db/models/query.py", line 262, in __len__
    self._fetch_all()
  File "/usr/local/lib/python3.9/site-packages/django/db/models/query.py", line 1324, in _fetch_all
    self._result_cache = list(self._iterable_class(self))
  File "/usr/local/lib/python3.9/site-packages/django/db/models/query.py", line 51, in __iter__
    results = compiler.execute_sql(chunked_fetch=self.chunked_fetch, chunk_size=self.chunk_size)
  File "/usr/local/lib/python3.9/site-packages/django/db/models/sql/compiler.py", line 1173, in execute_sql
    cursor = self.connection.cursor()
  File "/usr/local/lib/python3.9/site-packages/django/utils/asyncio.py", line 26, in inner
    return func(*args, **kwargs)
  File "/usr/local/lib/python3.9/site-packages/django/db/backends/base/base.py", line 259, in cursor
    return self._cursor()
  File "/usr/local/lib/python3.9/site-packages/django/db/backends/base/base.py", line 235, in _cursor
    self.ensure_connection()
  File "/usr/local/lib/python3.9/site-packages/django/utils/asyncio.py", line 26, in inner
    return func(*args, **kwargs)
  File "/usr/local/lib/python3.9/site-packages/django/db/backends/base/base.py", line 219, in ensure_connection
    self.connect()
  File "/usr/local/lib/python3.9/site-packages/django/db/utils.py", line 90, in __exit__
    raise dj_exc_value.with_traceback(traceback) from exc_value
  File "/usr/local/lib/python3.9/site-packages/django/db/backends/base/base.py", line 219, in ensure_connection
    self.connect()
  File "/usr/local/lib/python3.9/site-packages/django/utils/asyncio.py", line 26, in inner
    return func(*args, **kwargs)
  File "/usr/local/lib/python3.9/site-packages/django/db/backends/base/base.py", line 200, in connect
    self.connection = self.get_new_connection(conn_params)
  File "/usr/local/lib/python3.9/site-packages/django/utils/asyncio.py", line 26, in inner
    return func(*args, **kwargs)
  File "/usr/local/lib/python3.9/site-packages/django/db/backends/postgresql/base.py", line 187, in get_new_connection
    connection = Database.connect(**conn_params)
  File "/usr/local/lib/python3.9/site-packages/psycopg2/__init__.py", line 122, in connect
    conn = _connect(dsn, connection_factory=connection_factory, **kwasync)
django.db.utils.OperationalError: connection to server at "db" (172.18.0.2), port 5432 failed: fe_sendauth: no password supplied

[15/Mar/2022 16:02:56] |ERROR| Internal Server Error: /admin/
Traceback (most recent call last):
  File "/usr/local/lib/python3.9/site-packages/django/contrib/sessions/backends/base.py", line 233, in _get_session
    return self._session_cache
AttributeError: 'SessionStore' object has no attribute '_session_cache'

During handling of the above exception, another exception occurred:

Traceback (most recent call last):
  File "/usr/local/lib/python3.9/site-packages/django/db/backends/base/base.py", line 219, in ensure_connection
    self.connect()
  File "/usr/local/lib/python3.9/site-packages/django/utils/asyncio.py", line 26, in inner
    return func(*args, **kwargs)
  File "/usr/local/lib/python3.9/site-packages/django/db/backends/base/base.py", line 200, in connect
    self.connection = self.get_new_connection(conn_params)
  File "/usr/local/lib/python3.9/site-packages/django/utils/asyncio.py", line 26, in inner
    return func(*args, **kwargs)
  File "/usr/local/lib/python3.9/site-packages/django/db/backends/postgresql/base.py", line 187, in get_new_connection
    connection = Database.connect(**conn_params)
  File "/usr/local/lib/python3.9/site-packages/psycopg2/__init__.py", line 122, in connect
    conn = _connect(dsn, connection_factory=connection_factory, **kwasync)
psycopg2.OperationalError: connection to server at "db" (172.18.0.2), port 5432 failed: fe_sendauth: no password supplied


The above exception was the direct cause of the following exception:

Traceback (most recent call last):
  File "/usr/local/lib/python3.9/site-packages/django/core/handlers/exception.py", line 47, in inner
    response = get_response(request)
  File "/usr/local/lib/python3.9/site-packages/django/core/handlers/base.py", line 181, in _get_response
    response = wrapped_callback(request, *callback_args, **callback_kwargs)
  File "/usr/local/lib/python3.9/site-packages/django/contrib/admin/sites.py", line 250, in wrapper
    return self.admin_view(view, cacheable)(*args, **kwargs)
  File "/usr/local/lib/python3.9/site-packages/django/utils/decorators.py", line 130, in _wrapped_view
    response = view_func(request, *args, **kwargs)
  File "/usr/local/lib/python3.9/site-packages/django/views/decorators/cache.py", line 44, in _wrapped_view_func
    response = view_func(request, *args, **kwargs)
  File "/usr/local/lib/python3.9/site-packages/django/contrib/admin/sites.py", line 221, in inner
    if not self.has_permission(request):
  File "/usr/local/lib/python3.9/site-packages/django/contrib/admin/sites.py", line 195, in has_permission
    return request.user.is_active and request.user.is_staff
  File "/usr/local/lib/python3.9/site-packages/django/utils/functional.py", line 246, in inner
    self._setup()
  File "/usr/local/lib/python3.9/site-packages/django/utils/functional.py", line 382, in _setup
    self._wrapped = self._setupfunc()
  File "/usr/local/lib/python3.9/site-packages/django/contrib/auth/middleware.py", line 23, in <lambda>
    request.user = SimpleLazyObject(lambda: get_user(request))
  File "/usr/local/lib/python3.9/site-packages/django/contrib/auth/middleware.py", line 11, in get_user
    request._cached_user = auth.get_user(request)
  File "/usr/local/lib/python3.9/site-packages/django/contrib/auth/__init__.py", line 177, in get_user
    user_id = _get_user_session_key(request)
  File "/usr/local/lib/python3.9/site-packages/django/contrib/auth/__init__.py", line 60, in _get_user_session_key
    return get_user_model()._meta.pk.to_python(request.session[SESSION_KEY])
  File "/usr/local/lib/python3.9/site-packages/django/contrib/sessions/backends/base.py", line 65, in __getitem__
    return self._session[key]
  File "/usr/local/lib/python3.9/site-packages/django/contrib/sessions/backends/base.py", line 238, in _get_session
    self._session_cache = self.load()
  File "/usr/local/lib/python3.9/site-packages/django/contrib/sessions/backends/db.py", line 43, in load
    s = self._get_session_from_db()
  File "/usr/local/lib/python3.9/site-packages/django/contrib/sessions/backends/db.py", line 32, in _get_session_from_db
    return self.model.objects.get(
  File "/usr/local/lib/python3.9/site-packages/django/db/models/manager.py", line 85, in manager_method
    return getattr(self.get_queryset(), name)(*args, **kwargs)
  File "/usr/local/lib/python3.9/site-packages/django/db/models/query.py", line 431, in get
    num = len(clone)
  File "/usr/local/lib/python3.9/site-packages/django/db/models/query.py", line 262, in __len__
    self._fetch_all()
  File "/usr/local/lib/python3.9/site-packages/django/db/models/query.py", line 1324, in _fetch_all
    self._result_cache = list(self._iterable_class(self))
  File "/usr/local/lib/python3.9/site-packages/django/db/models/query.py", line 51, in __iter__
    results = compiler.execute_sql(chunked_fetch=self.chunked_fetch, chunk_size=self.chunk_size)
  File "/usr/local/lib/python3.9/site-packages/django/db/models/sql/compiler.py", line 1173, in execute_sql
    cursor = self.connection.cursor()
  File "/usr/local/lib/python3.9/site-packages/django/utils/asyncio.py", line 26, in inner
    return func(*args, **kwargs)
  File "/usr/local/lib/python3.9/site-packages/django/db/backends/base/base.py", line 259, in cursor
    return self._cursor()
  File "/usr/local/lib/python3.9/site-packages/django/db/backends/base/base.py", line 235, in _cursor
    self.ensure_connection()
  File "/usr/local/lib/python3.9/site-packages/django/utils/asyncio.py", line 26, in inner
    return func(*args, **kwargs)
  File "/usr/local/lib/python3.9/site-packages/django/db/backends/base/base.py", line 219, in ensure_connection
    self.connect()
  File "/usr/local/lib/python3.9/site-packages/django/db/utils.py", line 90, in __exit__
    raise dj_exc_value.with_traceback(traceback) from exc_value
  File "/usr/local/lib/python3.9/site-packages/django/db/backends/base/base.py", line 219, in ensure_connection
    self.connect()
  File "/usr/local/lib/python3.9/site-packages/django/utils/asyncio.py", line 26, in inner
    return func(*args, **kwargs)
  File "/usr/local/lib/python3.9/site-packages/django/db/backends/base/base.py", line 200, in connect
    self.connection = self.get_new_connection(conn_params)
  File "/usr/local/lib/python3.9/site-packages/django/utils/asyncio.py", line 26, in inner
    return func(*args, **kwargs)
  File "/usr/local/lib/python3.9/site-packages/django/db/backends/postgresql/base.py", line 187, in get_new_connection
    connection = Database.connect(**conn_params)
  File "/usr/local/lib/python3.9/site-packages/psycopg2/__init__.py", line 122, in connect
    conn = _connect(dsn, connection_factory=connection_factory, **kwasync)
django.db.utils.OperationalError: connection to server at "db" (172.18.0.2), port 5432 failed: fe_sendauth: no password supplied

